[2023-05-24 19:15:46,290], [ERROR], [Internal Server Error: /classes/], [C:\Users\root\Desktop\Project\venv\lib\site-packages\django\utils\log.py], [(<class 'django.template.exceptions.TemplateDoesNotExist'>, TemplateDoesNotExist('django_filters/rest_framework/form.html'), <traceback object at 0x00000211F5BE8840>)]
Traceback (most recent call last):
  File "C:\Users\root\Desktop\Project\venv\lib\site-packages\django\core\handlers\exception.py", line 55, in inner
    response = get_response(request)
  File "C:\Users\root\Desktop\Project\venv\lib\site-packages\django\core\handlers\base.py", line 220, in _get_response
    response = response.render()
  File "C:\Users\root\Desktop\Project\venv\lib\site-packages\django\template\response.py", line 114, in render
    self.content = self.rendered_content
  File "C:\Users\root\Desktop\Project\venv\lib\site-packages\rest_framework\response.py", line 70, in rendered_content
    ret = renderer.render(self.data, accepted_media_type, context)
  File "C:\Users\root\Desktop\Project\venv\lib\site-packages\rest_framework\renderers.py", line 723, in render
    context = self.get_context(data, accepted_media_type, renderer_context)
  File "C:\Users\root\Desktop\Project\venv\lib\site-packages\rest_framework\renderers.py", line 701, in get_context
    'filter_form': self.get_filter_form(data, view, request),
  File "C:\Users\root\Desktop\Project\venv\lib\site-packages\rest_framework\renderers.py", line 633, in get_filter_form
    html = backend().to_html(request, queryset, view)
  File "C:\Users\root\Desktop\Project\venv\lib\site-packages\django_filters\rest_framework\backends.py", line 81, in to_html
    template = loader.get_template(self.template)
  File "C:\Users\root\Desktop\Project\venv\lib\site-packages\django\template\loader.py", line 19, in get_template
    raise TemplateDoesNotExist(template_name, chain=chain)
django.template.exceptions.TemplateDoesNotExist: django_filters/rest_framework/form.html
[2023-05-24 19:15:46,290], [ERROR], ["GET /classes/ HTTP/1.1" 500 102633], [C:\Users\root\Desktop\Project\venv\lib\site-packages\django\core\servers\basehttp.py], [None]
[2023-05-24 19:16:16,790], [ERROR], [Internal Server Error: /classes/], [C:\Users\root\Desktop\Project\venv\lib\site-packages\django\utils\log.py], [(<class 'django.template.exceptions.TemplateDoesNotExist'>, TemplateDoesNotExist('django_filters/rest_framework/form.html'), <traceback object at 0x00000211F5A366C0>)]
Traceback (most recent call last):
  File "C:\Users\root\Desktop\Project\venv\lib\site-packages\django\core\handlers\exception.py", line 55, in inner
    response = get_response(request)
  File "C:\Users\root\Desktop\Project\venv\lib\site-packages\django\core\handlers\base.py", line 220, in _get_response
    response = response.render()
  File "C:\Users\root\Desktop\Project\venv\lib\site-packages\django\template\response.py", line 114, in render
    self.content = self.rendered_content
  File "C:\Users\root\Desktop\Project\venv\lib\site-packages\rest_framework\response.py", line 70, in rendered_content
    ret = renderer.render(self.data, accepted_media_type, context)
  File "C:\Users\root\Desktop\Project\venv\lib\site-packages\rest_framework\renderers.py", line 723, in render
    context = self.get_context(data, accepted_media_type, renderer_context)
  File "C:\Users\root\Desktop\Project\venv\lib\site-packages\rest_framework\renderers.py", line 701, in get_context
    'filter_form': self.get_filter_form(data, view, request),
  File "C:\Users\root\Desktop\Project\venv\lib\site-packages\rest_framework\renderers.py", line 633, in get_filter_form
    html = backend().to_html(request, queryset, view)
  File "C:\Users\root\Desktop\Project\venv\lib\site-packages\django_filters\rest_framework\backends.py", line 81, in to_html
    template = loader.get_template(self.template)
  File "C:\Users\root\Desktop\Project\venv\lib\site-packages\django\template\loader.py", line 19, in get_template
    raise TemplateDoesNotExist(template_name, chain=chain)
django.template.exceptions.TemplateDoesNotExist: django_filters/rest_framework/form.html
[2023-05-24 19:16:16,795], [ERROR], ["GET /classes/ HTTP/1.1" 500 102633], [C:\Users\root\Desktop\Project\venv\lib\site-packages\django\core\servers\basehttp.py], [None]
[2023-05-24 19:20:41,629], [ERROR], [Internal Server Error: /students/], [C:\Users\root\Desktop\Project\venv\lib\site-packages\django\utils\log.py], [(<class 'django.db.utils.IntegrityError'>, IntegrityError('NOT NULL constraint failed: rest_test_student.sclass_id'), <traceback object at 0x00000211F5A1FF80>)]
Traceback (most recent call last):
  File "C:\Users\root\Desktop\Project\venv\lib\site-packages\django\db\backends\utils.py", line 89, in _execute
    return self.cursor.execute(sql, params)
  File "C:\Users\root\Desktop\Project\venv\lib\site-packages\django\db\backends\sqlite3\base.py", line 328, in execute
    return super().execute(query, params)
sqlite3.IntegrityError: NOT NULL constraint failed: rest_test_student.sclass_id

The above exception was the direct cause of the following exception:

Traceback (most recent call last):
  File "C:\Users\root\Desktop\Project\venv\lib\site-packages\django\core\handlers\exception.py", line 55, in inner
    response = get_response(request)
  File "C:\Users\root\Desktop\Project\venv\lib\site-packages\django\core\handlers\base.py", line 197, in _get_response
    response = wrapped_callback(request, *callback_args, **callback_kwargs)
  File "C:\Users\root\Desktop\Project\venv\lib\site-packages\django\views\decorators\csrf.py", line 56, in wrapper_view
    return view_func(*args, **kwargs)
  File "C:\Users\root\Desktop\Project\venv\lib\site-packages\rest_framework\viewsets.py", line 125, in view
    return self.dispatch(request, *args, **kwargs)
  File "C:\Users\root\Desktop\Project\venv\lib\site-packages\rest_framework\views.py", line 509, in dispatch
    response = self.handle_exception(exc)
  File "C:\Users\root\Desktop\Project\venv\lib\site-packages\rest_framework\views.py", line 469, in handle_exception
    self.raise_uncaught_exception(exc)
  File "C:\Users\root\Desktop\Project\venv\lib\site-packages\rest_framework\views.py", line 480, in raise_uncaught_exception
    raise exc
  File "C:\Users\root\Desktop\Project\venv\lib\site-packages\rest_framework\views.py", line 506, in dispatch
    response = handler(request, *args, **kwargs)
  File "C:\Users\root\Desktop\Project\venv\lib\site-packages\rest_framework\mixins.py", line 19, in create
    self.perform_create(serializer)
  File "C:\Users\root\Desktop\Project\venv\lib\site-packages\rest_framework\mixins.py", line 24, in perform_create
    serializer.save()
  File "C:\Users\root\Desktop\Project\venv\lib\site-packages\rest_framework\serializers.py", line 212, in save
    self.instance = self.create(validated_data)
  File "C:\Users\root\Desktop\Project\venv\lib\site-packages\rest_framework\serializers.py", line 962, in create
    instance = ModelClass._default_manager.create(**validated_data)
  File "C:\Users\root\Desktop\Project\venv\lib\site-packages\django\db\models\manager.py", line 87, in manager_method
    return getattr(self.get_queryset(), name)(*args, **kwargs)
  File "C:\Users\root\Desktop\Project\venv\lib\site-packages\django\db\models\query.py", line 658, in create
    obj.save(force_insert=True, using=self.db)
  File "C:\Users\root\Desktop\Project\venv\lib\site-packages\django\db\models\base.py", line 814, in save
    self.save_base(
  File "C:\Users\root\Desktop\Project\venv\lib\site-packages\django\db\models\base.py", line 877, in save_base
    updated = self._save_table(
  File "C:\Users\root\Desktop\Project\venv\lib\site-packages\django\db\models\base.py", line 1020, in _save_table
    results = self._do_insert(
  File "C:\Users\root\Desktop\Project\venv\lib\site-packages\django\db\models\base.py", line 1061, in _do_insert
    return manager._insert(
  File "C:\Users\root\Desktop\Project\venv\lib\site-packages\django\db\models\manager.py", line 87, in manager_method
    return getattr(self.get_queryset(), name)(*args, **kwargs)
  File "C:\Users\root\Desktop\Project\venv\lib\site-packages\django\db\models\query.py", line 1805, in _insert
    return query.get_compiler(using=using).execute_sql(returning_fields)
  File "C:\Users\root\Desktop\Project\venv\lib\site-packages\django\db\models\sql\compiler.py", line 1820, in execute_sql
    cursor.execute(sql, params)
  File "C:\Users\root\Desktop\Project\venv\lib\site-packages\django\db\backends\utils.py", line 102, in execute
    return super().execute(sql, params)
  File "C:\Users\root\Desktop\Project\venv\lib\site-packages\django\db\backends\utils.py", line 67, in execute
    return self._execute_with_wrappers(
  File "C:\Users\root\Desktop\Project\venv\lib\site-packages\django\db\backends\utils.py", line 80, in _execute_with_wrappers
    return executor(sql, params, many, context)
  File "C:\Users\root\Desktop\Project\venv\lib\site-packages\django\db\backends\utils.py", line 84, in _execute
    with self.db.wrap_database_errors:
  File "C:\Users\root\Desktop\Project\venv\lib\site-packages\django\db\utils.py", line 91, in __exit__
    raise dj_exc_value.with_traceback(traceback) from exc_value
  File "C:\Users\root\Desktop\Project\venv\lib\site-packages\django\db\backends\utils.py", line 89, in _execute
    return self.cursor.execute(sql, params)
  File "C:\Users\root\Desktop\Project\venv\lib\site-packages\django\db\backends\sqlite3\base.py", line 328, in execute
    return super().execute(query, params)
django.db.utils.IntegrityError: NOT NULL constraint failed: rest_test_student.sclass_id
[2023-05-24 19:20:41,648], [ERROR], ["POST /students/ HTTP/1.1" 500 197639], [C:\Users\root\Desktop\Project\venv\lib\site-packages\django\core\servers\basehttp.py], [None]
[2023-05-24 19:20:53,017], [ERROR], [Internal Server Error: /students/], [C:\Users\root\Desktop\Project\venv\lib\site-packages\django\utils\log.py], [(<class 'django.db.utils.IntegrityError'>, IntegrityError('NOT NULL constraint failed: rest_test_student.sclass_id'), <traceback object at 0x00000211F5A365C0>)]
Traceback (most recent call last):
  File "C:\Users\root\Desktop\Project\venv\lib\site-packages\django\db\backends\utils.py", line 89, in _execute
    return self.cursor.execute(sql, params)
  File "C:\Users\root\Desktop\Project\venv\lib\site-packages\django\db\backends\sqlite3\base.py", line 328, in execute
    return super().execute(query, params)
sqlite3.IntegrityError: NOT NULL constraint failed: rest_test_student.sclass_id

The above exception was the direct cause of the following exception:

Traceback (most recent call last):
  File "C:\Users\root\Desktop\Project\venv\lib\site-packages\django\core\handlers\exception.py", line 55, in inner
    response = get_response(request)
  File "C:\Users\root\Desktop\Project\venv\lib\site-packages\django\core\handlers\base.py", line 197, in _get_response
    response = wrapped_callback(request, *callback_args, **callback_kwargs)
  File "C:\Users\root\Desktop\Project\venv\lib\site-packages\django\views\decorators\csrf.py", line 56, in wrapper_view
    return view_func(*args, **kwargs)
  File "C:\Users\root\Desktop\Project\venv\lib\site-packages\rest_framework\viewsets.py", line 125, in view
    return self.dispatch(request, *args, **kwargs)
  File "C:\Users\root\Desktop\Project\venv\lib\site-packages\rest_framework\views.py", line 509, in dispatch
    response = self.handle_exception(exc)
  File "C:\Users\root\Desktop\Project\venv\lib\site-packages\rest_framework\views.py", line 469, in handle_exception
    self.raise_uncaught_exception(exc)
  File "C:\Users\root\Desktop\Project\venv\lib\site-packages\rest_framework\views.py", line 480, in raise_uncaught_exception
    raise exc
  File "C:\Users\root\Desktop\Project\venv\lib\site-packages\rest_framework\views.py", line 506, in dispatch
    response = handler(request, *args, **kwargs)
  File "C:\Users\root\Desktop\Project\venv\lib\site-packages\rest_framework\mixins.py", line 19, in create
    self.perform_create(serializer)
  File "C:\Users\root\Desktop\Project\venv\lib\site-packages\rest_framework\mixins.py", line 24, in perform_create
    serializer.save()
  File "C:\Users\root\Desktop\Project\venv\lib\site-packages\rest_framework\serializers.py", line 212, in save
    self.instance = self.create(validated_data)
  File "C:\Users\root\Desktop\Project\venv\lib\site-packages\rest_framework\serializers.py", line 962, in create
    instance = ModelClass._default_manager.create(**validated_data)
  File "C:\Users\root\Desktop\Project\venv\lib\site-packages\django\db\models\manager.py", line 87, in manager_method
    return getattr(self.get_queryset(), name)(*args, **kwargs)
  File "C:\Users\root\Desktop\Project\venv\lib\site-packages\django\db\models\query.py", line 658, in create
    obj.save(force_insert=True, using=self.db)
  File "C:\Users\root\Desktop\Project\venv\lib\site-packages\django\db\models\base.py", line 814, in save
    self.save_base(
  File "C:\Users\root\Desktop\Project\venv\lib\site-packages\django\db\models\base.py", line 877, in save_base
    updated = self._save_table(
  File "C:\Users\root\Desktop\Project\venv\lib\site-packages\django\db\models\base.py", line 1020, in _save_table
    results = self._do_insert(
  File "C:\Users\root\Desktop\Project\venv\lib\site-packages\django\db\models\base.py", line 1061, in _do_insert
    return manager._insert(
  File "C:\Users\root\Desktop\Project\venv\lib\site-packages\django\db\models\manager.py", line 87, in manager_method
    return getattr(self.get_queryset(), name)(*args, **kwargs)
  File "C:\Users\root\Desktop\Project\venv\lib\site-packages\django\db\models\query.py", line 1805, in _insert
    return query.get_compiler(using=using).execute_sql(returning_fields)
  File "C:\Users\root\Desktop\Project\venv\lib\site-packages\django\db\models\sql\compiler.py", line 1820, in execute_sql
    cursor.execute(sql, params)
  File "C:\Users\root\Desktop\Project\venv\lib\site-packages\django\db\backends\utils.py", line 102, in execute
    return super().execute(sql, params)
  File "C:\Users\root\Desktop\Project\venv\lib\site-packages\django\db\backends\utils.py", line 67, in execute
    return self._execute_with_wrappers(
  File "C:\Users\root\Desktop\Project\venv\lib\site-packages\django\db\backends\utils.py", line 80, in _execute_with_wrappers
    return executor(sql, params, many, context)
  File "C:\Users\root\Desktop\Project\venv\lib\site-packages\django\db\backends\utils.py", line 84, in _execute
    with self.db.wrap_database_errors:
  File "C:\Users\root\Desktop\Project\venv\lib\site-packages\django\db\utils.py", line 91, in __exit__
    raise dj_exc_value.with_traceback(traceback) from exc_value
  File "C:\Users\root\Desktop\Project\venv\lib\site-packages\django\db\backends\utils.py", line 89, in _execute
    return self.cursor.execute(sql, params)
  File "C:\Users\root\Desktop\Project\venv\lib\site-packages\django\db\backends\sqlite3\base.py", line 328, in execute
    return super().execute(query, params)
django.db.utils.IntegrityError: NOT NULL constraint failed: rest_test_student.sclass_id
[2023-05-24 19:20:53,029], [ERROR], ["POST /students/ HTTP/1.1" 500 197639], [C:\Users\root\Desktop\Project\venv\lib\site-packages\django\core\servers\basehttp.py], [None]
[2023-05-24 19:21:13,791], [ERROR], [Internal Server Error: /students/], [C:\Users\root\Desktop\Project\venv\lib\site-packages\django\utils\log.py], [(<class 'django.db.utils.IntegrityError'>, IntegrityError('NOT NULL constraint failed: rest_test_student.sclass_id'), <traceback object at 0x00000211F5F09640>)]
Traceback (most recent call last):
  File "C:\Users\root\Desktop\Project\venv\lib\site-packages\django\db\backends\utils.py", line 89, in _execute
    return self.cursor.execute(sql, params)
  File "C:\Users\root\Desktop\Project\venv\lib\site-packages\django\db\backends\sqlite3\base.py", line 328, in execute
    return super().execute(query, params)
sqlite3.IntegrityError: NOT NULL constraint failed: rest_test_student.sclass_id

The above exception was the direct cause of the following exception:

Traceback (most recent call last):
  File "C:\Users\root\Desktop\Project\venv\lib\site-packages\django\core\handlers\exception.py", line 55, in inner
    response = get_response(request)
  File "C:\Users\root\Desktop\Project\venv\lib\site-packages\django\core\handlers\base.py", line 197, in _get_response
    response = wrapped_callback(request, *callback_args, **callback_kwargs)
  File "C:\Users\root\Desktop\Project\venv\lib\site-packages\django\views\decorators\csrf.py", line 56, in wrapper_view
    return view_func(*args, **kwargs)
  File "C:\Users\root\Desktop\Project\venv\lib\site-packages\rest_framework\viewsets.py", line 125, in view
    return self.dispatch(request, *args, **kwargs)
  File "C:\Users\root\Desktop\Project\venv\lib\site-packages\rest_framework\views.py", line 509, in dispatch
    response = self.handle_exception(exc)
  File "C:\Users\root\Desktop\Project\venv\lib\site-packages\rest_framework\views.py", line 469, in handle_exception
    self.raise_uncaught_exception(exc)
  File "C:\Users\root\Desktop\Project\venv\lib\site-packages\rest_framework\views.py", line 480, in raise_uncaught_exception
    raise exc
  File "C:\Users\root\Desktop\Project\venv\lib\site-packages\rest_framework\views.py", line 506, in dispatch
    response = handler(request, *args, **kwargs)
  File "C:\Users\root\Desktop\Project\venv\lib\site-packages\rest_framework\mixins.py", line 19, in create
    self.perform_create(serializer)
  File "C:\Users\root\Desktop\Project\venv\lib\site-packages\rest_framework\mixins.py", line 24, in perform_create
    serializer.save()
  File "C:\Users\root\Desktop\Project\venv\lib\site-packages\rest_framework\serializers.py", line 212, in save
    self.instance = self.create(validated_data)
  File "C:\Users\root\Desktop\Project\venv\lib\site-packages\rest_framework\serializers.py", line 962, in create
    instance = ModelClass._default_manager.create(**validated_data)
  File "C:\Users\root\Desktop\Project\venv\lib\site-packages\django\db\models\manager.py", line 87, in manager_method
    return getattr(self.get_queryset(), name)(*args, **kwargs)
  File "C:\Users\root\Desktop\Project\venv\lib\site-packages\django\db\models\query.py", line 658, in create
    obj.save(force_insert=True, using=self.db)
  File "C:\Users\root\Desktop\Project\venv\lib\site-packages\django\db\models\base.py", line 814, in save
    self.save_base(
  File "C:\Users\root\Desktop\Project\venv\lib\site-packages\django\db\models\base.py", line 877, in save_base
    updated = self._save_table(
  File "C:\Users\root\Desktop\Project\venv\lib\site-packages\django\db\models\base.py", line 1020, in _save_table
    results = self._do_insert(
  File "C:\Users\root\Desktop\Project\venv\lib\site-packages\django\db\models\base.py", line 1061, in _do_insert
    return manager._insert(
  File "C:\Users\root\Desktop\Project\venv\lib\site-packages\django\db\models\manager.py", line 87, in manager_method
    return getattr(self.get_queryset(), name)(*args, **kwargs)
  File "C:\Users\root\Desktop\Project\venv\lib\site-packages\django\db\models\query.py", line 1805, in _insert
    return query.get_compiler(using=using).execute_sql(returning_fields)
  File "C:\Users\root\Desktop\Project\venv\lib\site-packages\django\db\models\sql\compiler.py", line 1820, in execute_sql
    cursor.execute(sql, params)
  File "C:\Users\root\Desktop\Project\venv\lib\site-packages\django\db\backends\utils.py", line 102, in execute
    return super().execute(sql, params)
  File "C:\Users\root\Desktop\Project\venv\lib\site-packages\django\db\backends\utils.py", line 67, in execute
    return self._execute_with_wrappers(
  File "C:\Users\root\Desktop\Project\venv\lib\site-packages\django\db\backends\utils.py", line 80, in _execute_with_wrappers
    return executor(sql, params, many, context)
  File "C:\Users\root\Desktop\Project\venv\lib\site-packages\django\db\backends\utils.py", line 84, in _execute
    with self.db.wrap_database_errors:
  File "C:\Users\root\Desktop\Project\venv\lib\site-packages\django\db\utils.py", line 91, in __exit__
    raise dj_exc_value.with_traceback(traceback) from exc_value
  File "C:\Users\root\Desktop\Project\venv\lib\site-packages\django\db\backends\utils.py", line 89, in _execute
    return self.cursor.execute(sql, params)
  File "C:\Users\root\Desktop\Project\venv\lib\site-packages\django\db\backends\sqlite3\base.py", line 328, in execute
    return super().execute(query, params)
django.db.utils.IntegrityError: NOT NULL constraint failed: rest_test_student.sclass_id
[2023-05-24 19:21:13,814], [ERROR], ["POST /students/ HTTP/1.1" 500 196319], [C:\Users\root\Desktop\Project\venv\lib\site-packages\django\core\servers\basehttp.py], [None]
[2023-05-24 19:21:17,282], [ERROR], [Internal Server Error: /classes/], [C:\Users\root\Desktop\Project\venv\lib\site-packages\django\utils\log.py], [(<class 'django.template.exceptions.TemplateDoesNotExist'>, TemplateDoesNotExist('django_filters/rest_framework/form.html'), <traceback object at 0x00000211F5F06F40>)]
Traceback (most recent call last):
  File "C:\Users\root\Desktop\Project\venv\lib\site-packages\django\core\handlers\exception.py", line 55, in inner
    response = get_response(request)
  File "C:\Users\root\Desktop\Project\venv\lib\site-packages\django\core\handlers\base.py", line 220, in _get_response
    response = response.render()
  File "C:\Users\root\Desktop\Project\venv\lib\site-packages\django\template\response.py", line 114, in render
    self.content = self.rendered_content
  File "C:\Users\root\Desktop\Project\venv\lib\site-packages\rest_framework\response.py", line 70, in rendered_content
    ret = renderer.render(self.data, accepted_media_type, context)
  File "C:\Users\root\Desktop\Project\venv\lib\site-packages\rest_framework\renderers.py", line 723, in render
    context = self.get_context(data, accepted_media_type, renderer_context)
  File "C:\Users\root\Desktop\Project\venv\lib\site-packages\rest_framework\renderers.py", line 701, in get_context
    'filter_form': self.get_filter_form(data, view, request),
  File "C:\Users\root\Desktop\Project\venv\lib\site-packages\rest_framework\renderers.py", line 633, in get_filter_form
    html = backend().to_html(request, queryset, view)
  File "C:\Users\root\Desktop\Project\venv\lib\site-packages\django_filters\rest_framework\backends.py", line 81, in to_html
    template = loader.get_template(self.template)
  File "C:\Users\root\Desktop\Project\venv\lib\site-packages\django\template\loader.py", line 19, in get_template
    raise TemplateDoesNotExist(template_name, chain=chain)
django.template.exceptions.TemplateDoesNotExist: django_filters/rest_framework/form.html
[2023-05-24 19:21:17,282], [ERROR], ["GET /classes/ HTTP/1.1" 500 102768], [C:\Users\root\Desktop\Project\venv\lib\site-packages\django\core\servers\basehttp.py], [None]
[2023-05-24 19:22:53,178], [ERROR], [Internal Server Error: /classes/], [C:\Users\root\Desktop\Project\venv\lib\site-packages\django\utils\log.py], [(<class 'django.template.exceptions.TemplateDoesNotExist'>, TemplateDoesNotExist('django_filters/rest_framework/form.html'), <traceback object at 0x00000211F5A71180>)]
Traceback (most recent call last):
  File "C:\Users\root\Desktop\Project\venv\lib\site-packages\django\core\handlers\exception.py", line 55, in inner
    response = get_response(request)
  File "C:\Users\root\Desktop\Project\venv\lib\site-packages\django\core\handlers\base.py", line 220, in _get_response
    response = response.render()
  File "C:\Users\root\Desktop\Project\venv\lib\site-packages\django\template\response.py", line 114, in render
    self.content = self.rendered_content
  File "C:\Users\root\Desktop\Project\venv\lib\site-packages\rest_framework\response.py", line 70, in rendered_content
    ret = renderer.render(self.data, accepted_media_type, context)
  File "C:\Users\root\Desktop\Project\venv\lib\site-packages\rest_framework\renderers.py", line 723, in render
    context = self.get_context(data, accepted_media_type, renderer_context)
  File "C:\Users\root\Desktop\Project\venv\lib\site-packages\rest_framework\renderers.py", line 701, in get_context
    'filter_form': self.get_filter_form(data, view, request),
  File "C:\Users\root\Desktop\Project\venv\lib\site-packages\rest_framework\renderers.py", line 633, in get_filter_form
    html = backend().to_html(request, queryset, view)
  File "C:\Users\root\Desktop\Project\venv\lib\site-packages\django_filters\rest_framework\backends.py", line 81, in to_html
    template = loader.get_template(self.template)
  File "C:\Users\root\Desktop\Project\venv\lib\site-packages\django\template\loader.py", line 19, in get_template
    raise TemplateDoesNotExist(template_name, chain=chain)
django.template.exceptions.TemplateDoesNotExist: django_filters/rest_framework/form.html
[2023-05-24 19:22:53,178], [ERROR], ["GET /classes/ HTTP/1.1" 500 102905], [C:\Users\root\Desktop\Project\venv\lib\site-packages\django\core\servers\basehttp.py], [None]
[2023-05-24 19:23:37,318], [ERROR], [Internal Server Error: /classes/], [C:\Users\root\Desktop\Project\venv\lib\site-packages\django\utils\log.py], [(<class 'django.template.exceptions.TemplateDoesNotExist'>, TemplateDoesNotExist('django_filters/rest_framework/form.html'), <traceback object at 0x00000211F5C08B40>)]
Traceback (most recent call last):
  File "C:\Users\root\Desktop\Project\venv\lib\site-packages\django\core\handlers\exception.py", line 55, in inner
    response = get_response(request)
  File "C:\Users\root\Desktop\Project\venv\lib\site-packages\django\core\handlers\base.py", line 220, in _get_response
    response = response.render()
  File "C:\Users\root\Desktop\Project\venv\lib\site-packages\django\template\response.py", line 114, in render
    self.content = self.rendered_content
  File "C:\Users\root\Desktop\Project\venv\lib\site-packages\rest_framework\response.py", line 70, in rendered_content
    ret = renderer.render(self.data, accepted_media_type, context)
  File "C:\Users\root\Desktop\Project\venv\lib\site-packages\rest_framework\renderers.py", line 723, in render
    context = self.get_context(data, accepted_media_type, renderer_context)
  File "C:\Users\root\Desktop\Project\venv\lib\site-packages\rest_framework\renderers.py", line 701, in get_context
    'filter_form': self.get_filter_form(data, view, request),
  File "C:\Users\root\Desktop\Project\venv\lib\site-packages\rest_framework\renderers.py", line 633, in get_filter_form
    html = backend().to_html(request, queryset, view)
  File "C:\Users\root\Desktop\Project\venv\lib\site-packages\django_filters\rest_framework\backends.py", line 81, in to_html
    template = loader.get_template(self.template)
  File "C:\Users\root\Desktop\Project\venv\lib\site-packages\django\template\loader.py", line 19, in get_template
    raise TemplateDoesNotExist(template_name, chain=chain)
django.template.exceptions.TemplateDoesNotExist: django_filters/rest_framework/form.html
[2023-05-24 19:23:37,324], [ERROR], ["GET /classes/ HTTP/1.1" 500 102768], [C:\Users\root\Desktop\Project\venv\lib\site-packages\django\core\servers\basehttp.py], [None]
[2023-05-24 19:24:33,115], [ERROR], [Internal Server Error: /classes/], [C:\Users\root\Desktop\Project\venv\lib\site-packages\django\utils\log.py], [(<class 'django.db.utils.IntegrityError'>, IntegrityError('NOT NULL constraint failed: rest_test_sclass.school_id'), <traceback object at 0x0000013F5E35CE80>)]
Traceback (most recent call last):
  File "C:\Users\root\Desktop\Project\venv\lib\site-packages\django\db\backends\utils.py", line 89, in _execute
    return self.cursor.execute(sql, params)
  File "C:\Users\root\Desktop\Project\venv\lib\site-packages\django\db\backends\sqlite3\base.py", line 328, in execute
    return super().execute(query, params)
sqlite3.IntegrityError: NOT NULL constraint failed: rest_test_sclass.school_id

The above exception was the direct cause of the following exception:

Traceback (most recent call last):
  File "C:\Users\root\Desktop\Project\venv\lib\site-packages\django\core\handlers\exception.py", line 55, in inner
    response = get_response(request)
  File "C:\Users\root\Desktop\Project\venv\lib\site-packages\django\core\handlers\base.py", line 197, in _get_response
    response = wrapped_callback(request, *callback_args, **callback_kwargs)
  File "C:\Users\root\Desktop\Project\venv\lib\site-packages\django\views\decorators\csrf.py", line 56, in wrapper_view
    return view_func(*args, **kwargs)
  File "C:\Users\root\Desktop\Project\venv\lib\site-packages\rest_framework\viewsets.py", line 125, in view
    return self.dispatch(request, *args, **kwargs)
  File "C:\Users\root\Desktop\Project\venv\lib\site-packages\rest_framework\views.py", line 509, in dispatch
    response = self.handle_exception(exc)
  File "C:\Users\root\Desktop\Project\venv\lib\site-packages\rest_framework\views.py", line 469, in handle_exception
    self.raise_uncaught_exception(exc)
  File "C:\Users\root\Desktop\Project\venv\lib\site-packages\rest_framework\views.py", line 480, in raise_uncaught_exception
    raise exc
  File "C:\Users\root\Desktop\Project\venv\lib\site-packages\rest_framework\views.py", line 506, in dispatch
    response = handler(request, *args, **kwargs)
  File "C:\Users\root\Desktop\Project\venv\lib\site-packages\rest_framework\mixins.py", line 19, in create
    self.perform_create(serializer)
  File "C:\Users\root\Desktop\Project\venv\lib\site-packages\rest_framework\mixins.py", line 24, in perform_create
    serializer.save()
  File "C:\Users\root\Desktop\Project\venv\lib\site-packages\rest_framework\serializers.py", line 212, in save
    self.instance = self.create(validated_data)
  File "C:\Users\root\Desktop\Project\venv\lib\site-packages\rest_framework\serializers.py", line 962, in create
    instance = ModelClass._default_manager.create(**validated_data)
  File "C:\Users\root\Desktop\Project\venv\lib\site-packages\django\db\models\manager.py", line 87, in manager_method
    return getattr(self.get_queryset(), name)(*args, **kwargs)
  File "C:\Users\root\Desktop\Project\venv\lib\site-packages\django\db\models\query.py", line 658, in create
    obj.save(force_insert=True, using=self.db)
  File "C:\Users\root\Desktop\Project\venv\lib\site-packages\django\db\models\base.py", line 814, in save
    self.save_base(
  File "C:\Users\root\Desktop\Project\venv\lib\site-packages\django\db\models\base.py", line 877, in save_base
    updated = self._save_table(
  File "C:\Users\root\Desktop\Project\venv\lib\site-packages\django\db\models\base.py", line 1020, in _save_table
    results = self._do_insert(
  File "C:\Users\root\Desktop\Project\venv\lib\site-packages\django\db\models\base.py", line 1061, in _do_insert
    return manager._insert(
  File "C:\Users\root\Desktop\Project\venv\lib\site-packages\django\db\models\manager.py", line 87, in manager_method
    return getattr(self.get_queryset(), name)(*args, **kwargs)
  File "C:\Users\root\Desktop\Project\venv\lib\site-packages\django\db\models\query.py", line 1805, in _insert
    return query.get_compiler(using=using).execute_sql(returning_fields)
  File "C:\Users\root\Desktop\Project\venv\lib\site-packages\django\db\models\sql\compiler.py", line 1820, in execute_sql
    cursor.execute(sql, params)
  File "C:\Users\root\Desktop\Project\venv\lib\site-packages\django\db\backends\utils.py", line 102, in execute
    return super().execute(sql, params)
  File "C:\Users\root\Desktop\Project\venv\lib\site-packages\django\db\backends\utils.py", line 67, in execute
    return self._execute_with_wrappers(
  File "C:\Users\root\Desktop\Project\venv\lib\site-packages\django\db\backends\utils.py", line 80, in _execute_with_wrappers
    return executor(sql, params, many, context)
  File "C:\Users\root\Desktop\Project\venv\lib\site-packages\django\db\backends\utils.py", line 84, in _execute
    with self.db.wrap_database_errors:
  File "C:\Users\root\Desktop\Project\venv\lib\site-packages\django\db\utils.py", line 91, in __exit__
    raise dj_exc_value.with_traceback(traceback) from exc_value
  File "C:\Users\root\Desktop\Project\venv\lib\site-packages\django\db\backends\utils.py", line 89, in _execute
    return self.cursor.execute(sql, params)
  File "C:\Users\root\Desktop\Project\venv\lib\site-packages\django\db\backends\sqlite3\base.py", line 328, in execute
    return super().execute(query, params)
django.db.utils.IntegrityError: NOT NULL constraint failed: rest_test_sclass.school_id
[2023-05-24 19:24:33,128], [ERROR], ["POST /classes/ HTTP/1.1" 500 197711], [C:\Users\root\Desktop\Project\venv\lib\site-packages\django\core\servers\basehttp.py], [None]
[2023-05-24 19:31:38,077], [ERROR], [Internal Server Error: /classes/], [C:\Users\root\Desktop\Project\venv\lib\site-packages\django\utils\log.py], [(<class 'django.db.utils.IntegrityError'>, IntegrityError('NOT NULL constraint failed: rest_test_sclass.school_id'), <traceback object at 0x0000013F5E5F1B00>)]
Traceback (most recent call last):
  File "C:\Users\root\Desktop\Project\venv\lib\site-packages\django\db\backends\utils.py", line 89, in _execute
    return self.cursor.execute(sql, params)
  File "C:\Users\root\Desktop\Project\venv\lib\site-packages\django\db\backends\sqlite3\base.py", line 328, in execute
    return super().execute(query, params)
sqlite3.IntegrityError: NOT NULL constraint failed: rest_test_sclass.school_id

The above exception was the direct cause of the following exception:

Traceback (most recent call last):
  File "C:\Users\root\Desktop\Project\venv\lib\site-packages\django\core\handlers\exception.py", line 55, in inner
    response = get_response(request)
  File "C:\Users\root\Desktop\Project\venv\lib\site-packages\django\core\handlers\base.py", line 197, in _get_response
    response = wrapped_callback(request, *callback_args, **callback_kwargs)
  File "C:\Users\root\Desktop\Project\venv\lib\site-packages\django\views\decorators\csrf.py", line 56, in wrapper_view
    return view_func(*args, **kwargs)
  File "C:\Users\root\Desktop\Project\venv\lib\site-packages\rest_framework\viewsets.py", line 125, in view
    return self.dispatch(request, *args, **kwargs)
  File "C:\Users\root\Desktop\Project\venv\lib\site-packages\rest_framework\views.py", line 509, in dispatch
    response = self.handle_exception(exc)
  File "C:\Users\root\Desktop\Project\venv\lib\site-packages\rest_framework\views.py", line 469, in handle_exception
    self.raise_uncaught_exception(exc)
  File "C:\Users\root\Desktop\Project\venv\lib\site-packages\rest_framework\views.py", line 480, in raise_uncaught_exception
    raise exc
  File "C:\Users\root\Desktop\Project\venv\lib\site-packages\rest_framework\views.py", line 506, in dispatch
    response = handler(request, *args, **kwargs)
  File "C:\Users\root\Desktop\Project\venv\lib\site-packages\rest_framework\mixins.py", line 19, in create
    self.perform_create(serializer)
  File "C:\Users\root\Desktop\Project\venv\lib\site-packages\rest_framework\mixins.py", line 24, in perform_create
    serializer.save()
  File "C:\Users\root\Desktop\Project\venv\lib\site-packages\rest_framework\serializers.py", line 212, in save
    self.instance = self.create(validated_data)
  File "C:\Users\root\Desktop\Project\venv\lib\site-packages\rest_framework\serializers.py", line 962, in create
    instance = ModelClass._default_manager.create(**validated_data)
  File "C:\Users\root\Desktop\Project\venv\lib\site-packages\django\db\models\manager.py", line 87, in manager_method
    return getattr(self.get_queryset(), name)(*args, **kwargs)
  File "C:\Users\root\Desktop\Project\venv\lib\site-packages\django\db\models\query.py", line 658, in create
    obj.save(force_insert=True, using=self.db)
  File "C:\Users\root\Desktop\Project\venv\lib\site-packages\django\db\models\base.py", line 814, in save
    self.save_base(
  File "C:\Users\root\Desktop\Project\venv\lib\site-packages\django\db\models\base.py", line 877, in save_base
    updated = self._save_table(
  File "C:\Users\root\Desktop\Project\venv\lib\site-packages\django\db\models\base.py", line 1020, in _save_table
    results = self._do_insert(
  File "C:\Users\root\Desktop\Project\venv\lib\site-packages\django\db\models\base.py", line 1061, in _do_insert
    return manager._insert(
  File "C:\Users\root\Desktop\Project\venv\lib\site-packages\django\db\models\manager.py", line 87, in manager_method
    return getattr(self.get_queryset(), name)(*args, **kwargs)
  File "C:\Users\root\Desktop\Project\venv\lib\site-packages\django\db\models\query.py", line 1805, in _insert
    return query.get_compiler(using=using).execute_sql(returning_fields)
  File "C:\Users\root\Desktop\Project\venv\lib\site-packages\django\db\models\sql\compiler.py", line 1820, in execute_sql
    cursor.execute(sql, params)
  File "C:\Users\root\Desktop\Project\venv\lib\site-packages\django\db\backends\utils.py", line 102, in execute
    return super().execute(sql, params)
  File "C:\Users\root\Desktop\Project\venv\lib\site-packages\django\db\backends\utils.py", line 67, in execute
    return self._execute_with_wrappers(
  File "C:\Users\root\Desktop\Project\venv\lib\site-packages\django\db\backends\utils.py", line 80, in _execute_with_wrappers
    return executor(sql, params, many, context)
  File "C:\Users\root\Desktop\Project\venv\lib\site-packages\django\db\backends\utils.py", line 84, in _execute
    with self.db.wrap_database_errors:
  File "C:\Users\root\Desktop\Project\venv\lib\site-packages\django\db\utils.py", line 91, in __exit__
    raise dj_exc_value.with_traceback(traceback) from exc_value
  File "C:\Users\root\Desktop\Project\venv\lib\site-packages\django\db\backends\utils.py", line 89, in _execute
    return self.cursor.execute(sql, params)
  File "C:\Users\root\Desktop\Project\venv\lib\site-packages\django\db\backends\sqlite3\base.py", line 328, in execute
    return super().execute(query, params)
django.db.utils.IntegrityError: NOT NULL constraint failed: rest_test_sclass.school_id
[2023-05-24 19:31:38,087], [ERROR], ["POST /classes/ HTTP/1.1" 500 197575], [C:\Users\root\Desktop\Project\venv\lib\site-packages\django\core\servers\basehttp.py], [None]
[2023-05-24 19:41:30,474], [ERROR], [Internal Server Error: /classes/], [C:\Users\root\Desktop\Project\venv\lib\site-packages\django\utils\log.py], [(<class 'django.db.utils.IntegrityError'>, IntegrityError('NOT NULL constraint failed: rest_test_sclass.school_id'), <traceback object at 0x0000023BC6963D80>)]
Traceback (most recent call last):
  File "C:\Users\root\Desktop\Project\venv\lib\site-packages\django\db\backends\utils.py", line 89, in _execute
    return self.cursor.execute(sql, params)
  File "C:\Users\root\Desktop\Project\venv\lib\site-packages\django\db\backends\sqlite3\base.py", line 328, in execute
    return super().execute(query, params)
sqlite3.IntegrityError: NOT NULL constraint failed: rest_test_sclass.school_id

The above exception was the direct cause of the following exception:

Traceback (most recent call last):
  File "C:\Users\root\Desktop\Project\venv\lib\site-packages\django\core\handlers\exception.py", line 55, in inner
    response = get_response(request)
  File "C:\Users\root\Desktop\Project\venv\lib\site-packages\django\core\handlers\base.py", line 197, in _get_response
    response = wrapped_callback(request, *callback_args, **callback_kwargs)
  File "C:\Users\root\Desktop\Project\venv\lib\site-packages\django\views\decorators\csrf.py", line 56, in wrapper_view
    return view_func(*args, **kwargs)
  File "C:\Users\root\Desktop\Project\venv\lib\site-packages\rest_framework\viewsets.py", line 125, in view
    return self.dispatch(request, *args, **kwargs)
  File "C:\Users\root\Desktop\Project\venv\lib\site-packages\rest_framework\views.py", line 509, in dispatch
    response = self.handle_exception(exc)
  File "C:\Users\root\Desktop\Project\venv\lib\site-packages\rest_framework\views.py", line 469, in handle_exception
    self.raise_uncaught_exception(exc)
  File "C:\Users\root\Desktop\Project\venv\lib\site-packages\rest_framework\views.py", line 480, in raise_uncaught_exception
    raise exc
  File "C:\Users\root\Desktop\Project\venv\lib\site-packages\rest_framework\views.py", line 506, in dispatch
    response = handler(request, *args, **kwargs)
  File "C:\Users\root\Desktop\Project\venv\lib\site-packages\rest_framework\mixins.py", line 19, in create
    self.perform_create(serializer)
  File "C:\Users\root\Desktop\Project\venv\lib\site-packages\rest_framework\mixins.py", line 24, in perform_create
    serializer.save()
  File "C:\Users\root\Desktop\Project\venv\lib\site-packages\rest_framework\serializers.py", line 212, in save
    self.instance = self.create(validated_data)
  File "C:\Users\root\Desktop\Project\venv\lib\site-packages\rest_framework\serializers.py", line 962, in create
    instance = ModelClass._default_manager.create(**validated_data)
  File "C:\Users\root\Desktop\Project\venv\lib\site-packages\django\db\models\manager.py", line 87, in manager_method
    return getattr(self.get_queryset(), name)(*args, **kwargs)
  File "C:\Users\root\Desktop\Project\venv\lib\site-packages\django\db\models\query.py", line 658, in create
    obj.save(force_insert=True, using=self.db)
  File "C:\Users\root\Desktop\Project\venv\lib\site-packages\django\db\models\base.py", line 814, in save
    self.save_base(
  File "C:\Users\root\Desktop\Project\venv\lib\site-packages\django\db\models\base.py", line 877, in save_base
    updated = self._save_table(
  File "C:\Users\root\Desktop\Project\venv\lib\site-packages\django\db\models\base.py", line 1020, in _save_table
    results = self._do_insert(
  File "C:\Users\root\Desktop\Project\venv\lib\site-packages\django\db\models\base.py", line 1061, in _do_insert
    return manager._insert(
  File "C:\Users\root\Desktop\Project\venv\lib\site-packages\django\db\models\manager.py", line 87, in manager_method
    return getattr(self.get_queryset(), name)(*args, **kwargs)
  File "C:\Users\root\Desktop\Project\venv\lib\site-packages\django\db\models\query.py", line 1805, in _insert
    return query.get_compiler(using=using).execute_sql(returning_fields)
  File "C:\Users\root\Desktop\Project\venv\lib\site-packages\django\db\models\sql\compiler.py", line 1820, in execute_sql
    cursor.execute(sql, params)
  File "C:\Users\root\Desktop\Project\venv\lib\site-packages\django\db\backends\utils.py", line 102, in execute
    return super().execute(sql, params)
  File "C:\Users\root\Desktop\Project\venv\lib\site-packages\django\db\backends\utils.py", line 67, in execute
    return self._execute_with_wrappers(
  File "C:\Users\root\Desktop\Project\venv\lib\site-packages\django\db\backends\utils.py", line 80, in _execute_with_wrappers
    return executor(sql, params, many, context)
  File "C:\Users\root\Desktop\Project\venv\lib\site-packages\django\db\backends\utils.py", line 84, in _execute
    with self.db.wrap_database_errors:
  File "C:\Users\root\Desktop\Project\venv\lib\site-packages\django\db\utils.py", line 91, in __exit__
    raise dj_exc_value.with_traceback(traceback) from exc_value
  File "C:\Users\root\Desktop\Project\venv\lib\site-packages\django\db\backends\utils.py", line 89, in _execute
    return self.cursor.execute(sql, params)
  File "C:\Users\root\Desktop\Project\venv\lib\site-packages\django\db\backends\sqlite3\base.py", line 328, in execute
    return super().execute(query, params)
django.db.utils.IntegrityError: NOT NULL constraint failed: rest_test_sclass.school_id
[2023-05-24 19:41:30,491], [ERROR], ["POST /classes/ HTTP/1.1" 500 197711], [C:\Users\root\Desktop\Project\venv\lib\site-packages\django\core\servers\basehttp.py], [None]
